Workbook

Sheet 📊 Dashboard
B1: 🚀 PERSONAL GROWTH SPRINT 2026 — Progress Dashboard
B2: Saimir Baci · June 1 – August 31, 2026 · 5 Pillars · 2–3 hrs/day
B5: PILLAR | C5: Target Hrs | D5: Logged Hrs | E5: % Complete | F5: M1 Milestone | G5: M2 Milestone | H5: M3 Milestone
B6: 🧠 LLM & RLHF | C6: 72 | D6: ='📅 Weekly Log'!C100 -> 0 | E6: =IF(C6=0,0,D6/C6) -> 0 | F6: ⬜ Pending | G6: ⬜ Pending | H6: ⬜ Pending
B7: ⚡ Inference HW | C7: 72 | D7: ='📅 Weekly Log'!D100 -> 0 | E7: =IF(C7=0,0,D7/C7) -> 0 | F7: ⬜ Pending | G7: ⬜ Pending | H7: ⬜ Pending
B8: 🤝 Tech Sales | C8: 72 | D8: ='📅 Weekly Log'!E100 -> 0 | E8: =IF(C8=0,0,D8/C8) -> 0 | F8: ⬜ Pending | G8: ⬜ Pending | H8: ⬜ Pending
B9: 🗣️ Communication | C9: 54 | D9: ='📅 Weekly Log'!F100 -> 0 | E9: =IF(C9=0,0,D9/C9) -> 0 | F9: ⬜ Pending | G9: ⬜ Pending | H9: ⬜ Pending
B10: 🎙️ Voice | C10: 36 | D10: ='📅 Weekly Log'!G100 -> 0 | E10: =IF(C10=0,0,D10/C10) -> 0 | F10: ⬜ Pending | G10: ⬜ Pending | H10: ⬜ Pending
B13: Milestone Status: ⬜ Pending 🟡 In Progress ✅ Complete ❌ Missed
B15: WEEKLY HABIT STREAK (update manually each Sunday)
B16: Wk 1 | C16: Wk 2 | D16: Wk 3 | E16: Wk 4 | F16: Wk 5 | G16: Wk 6 | H16: Wk 7
B17: Voice ✅?
B18: Study hrs
B19: Quality (1-5)
B22: MONTHLY REFLECTIONS
B23: June 2026
B24: Top 3 wins:
B25: What to improve:
B26: Key insight:
B28: July 2026
B29: Top 3 wins:
B30: What to improve:
B31: Key insight:
... B36: Key insight:

Sheet 📅 Weekly Log
B1: 📅 Daily Learning Log — June–August 2026
B2: Log each session below. Complete the 'Note' column — even one sentence. Your streak matters more than your score.
B4: Date | C4: 🧠 LLM (hrs) | D4: ⚡ HW (hrs) | E4: 🤝 Sales (hrs) | F4: 🗣️ Comm (hrs) | G4: 🎙️ Voice (Y/N) | H4: Total (hrs) | I4: Energy (1–5) | J4: Key Learning / Note
B5: 46174 | H5: =SUM(C5:F5) -> 0
B6: 46175 | H6: =SUM(C6:F6) -> 0
B7: 46176 | H7: =SUM(C7:F7) -> 0
B8: 46177 | H8: =SUM(C8:F8) -> 0
B9: 46178 | H9: =SUM(C9:F9) -> 0
B10: 46179 | H10: =SUM(C10:F10) -> 0
B11: 46180 | C11: — Review Day —
B12: 46181 | H12: =SUM(C12:F12) -> 0
B13: 46182 | H13: =SUM(C13:F13) -> 0
B14: 46183 | H14: =SUM(C14:F14) -> 0
B15: 46184 | H15: =SUM(C15:F15) -> 0
B16: 46185 | H16: =SUM(C16:F16) -> 0
B17: 46186 | H17: =SUM(C17:F17) -> 0
B18: 46187 | C18: — Review Day —
B19: 46188 | H19: =SUM(C19:F19) -> 0
B20: 46189 | H20: =SUM(C20:F20) -> 0
B21: 46190 | H21: =SUM(C21:F21) -> 0
B22: 46191 | H22: =SUM(C22:F22) -> 0
B23: 46192 | H23: =SUM(C23:F23) -> 0
B24: 46193 | H24: =SUM(C24:F24) -> 0
B25: 46194 | C25: — Review Day —
B26: 46195 | H26: =SUM(C26:F26) -> 0
B27: 46196 | H27: =SUM(C27:F27) -> 0
B28: 46197 | H28: =SUM(C28:F28) -> 0
B29: 46198 | H29: =SUM(C29:F29) -> 0
B30: 46199 | H30: =SUM(C30:F30) -> 0
B31: 46200 | H31: =SUM(C31:F31) -> 0
B32: 46201 | C32: — Review Day —
B33: 46202 | H33: =SUM(C33:F33) -> 0
B34: 46203 | H34: =SUM(C34:F34) -> 0
B35: 46204 | H35: =SUM(C35:F35) -> 0
B36: 46205 | H36: =SUM(C36:F36) -> 0
B37: 46206 | H37: =SUM(C37:F37) -> 0
B38: 46207 | H38: =SUM(C38:F38) -> 0
B39: 46208 | C39: — Review Day —
B40: 46209 | H40: =SUM(C40:F40) -> 0
B41: 46210 | H41: =SUM(C41:F41) -> 0
...

Sheet 🧠 LLM & RLHF
B1: 🧠 LLM Architectures & RLHF — Curriculum & Progress
B2: Check off topics as you complete them. Add notes in the 'Notes' column as you go.
B4: Wk | C4: Topic / Exercise | D4: Resource | E4: Status | F4: Notes
B5: MONTH 1: JUNE — Foundations
B6: W1 | C6: Transformer architecture: multi-head attention, positional encoding, layer norm | D6: Annotated Transformer (Harvard NLP); Karpathy 'makemore' / 'nanoGPT' | E6: ⬜ Todo
B7: W1 | C7: Self-attention mechanics: Q, K, V matrices; scaled dot-product attention | D7: Attention Is All You Need (Vaswani et al., 2017) | E7: ⬜ Todo
B8: W2 | C8: Tokenisation: BPE, SentencePiece, byte-level BPE; build a tiny tokeniser | D8: Karpathy 'minBPE' repo | E8: ⬜ Todo
B9: W2 | C9: Pre-training objective: causal language modelling, next-token prediction, loss landscape | D9: Scaling Laws paper (Kaplan et al., 2020) | E9: ⬜ Todo
B10: W3 | C10: Supervised Fine-Tuning (SFT): datasets, instruction formats, loss masking | D10: Hugging Face TRL docs; Alpaca paper | E10: ⬜ Todo
B11: W3 | C11: Parameter-efficient fine-tuning: LoRA, QLoRA, prefix tuning — implement LoRA layer | D11: LoRA paper (Hu et al., 2021); LlamaFactory repo | E11: ⬜ Todo
B12: W4 | C12: RLHF: reward modelling from preferences, PPO algorithm basics | D12: InstructGPT paper (Ouyang et al., 2022) | E12: ⬜ Todo
B13: W4 | C13: PPO implementation: policy, value head, KL penalty, clip objective | D13: CleanRL PPO implementation; TRL PPO trainer | E13: ⬜ Todo
B15: MONTH 2: JULY — Advanced Alignment
B16: W5 | C16: Direct Preference Optimisation (DPO): derivation, why it avoids RL instability | D16: DPO paper (Rafailov et al., 2023) | E16: ⬜ Todo
B17: W5 | C17: RLAIF and Constitutional AI: self-critique loop, red-teaming with Claude | D17: Constitutional AI paper (Bai et al., 2022) | E17: ⬜ Todo
B18: W6 | C18: Mixture of Experts (MoE): routing, sparse activation, Mixtral architecture | D18: Switch Transformer paper; Mixtral technical report | E18: ⬜ Todo
B19: W6 | C19: State-space models: S4, Mamba, selective state spaces — conceptual understanding | D19: Mamba paper (Gu & Dao, 2023) | E19: ⬜ Todo
B20: W7 | C20: LLM evaluation: MMLU, HellaSwag, TruthfulQA; benchmark pitfalls and Goodhart's Law | D20: Big-Bench; HELM evaluation framework docs | E20: ⬜ Todo
B21: W7 | C21: Safety evaluation: red-teaming techniques, jailbreak categories, refusal training | D21: Anthropic red-teaming paper; Llama Guard | E21: ⬜ Todo
B22: W8 | C22: RAG architecture: chunking, embedding, vector search (FAISS/Chroma), reranking | D22: LangChain / LlamaIndex docs; ColBERT paper | E22: ⬜ Todo
B23: W8 | C23: Hybrid search: BM25 + dense retrieval; reciprocal rank fusion | D23: BEIR benchmark paper | E23: ⬜ Todo
B25: MONTH 3: AUGUST — Applied & Frontier
B26: W9 | C26: Multi-modal models: ViT image encoder, LLaVA architecture, image-text alignment | D26: LLaVA paper (Liu et al., 2023); Flamingo paper | E26: ⬜ Todo
B27: W9 | C27: Vision tokenisation: patch embeddings, cross-attention vs early fusion | D27: BLIP-2 paper | E27: ⬜ Todo
B28: W10 | C28: LLM agents: ReAct prompting, tool-use, function calling, memory types | D28: ReAct paper; OpenAI function calling docs | E28: ⬜ Todo
B29: W10 | C29: Agentic loops: planning, reflection, multi-agent coordination (brief survey) | D29: AutoGPT, CrewAI, LangGraph docs | E29: ⬜ Todo
B30: W11 | C30: Quantisation: GPTQ, GGUF, AWQ — what changes in the weights, what doesn't | D30: GPTQ paper; llama.cpp repo | E30: ⬜ Todo
B31: W11 | C31: Speculative decoding: draft model, verification, throughput gains | D31: Speculative decoding paper (Leviathan et al., 2022) | E31: ⬜ Todo
B32: W12 | C32: Personal synthesis: write 2-page technical brief on one frontier topic | D32: Your choice — publish on LinkedIn or internal doc | E32: ⬜ Todo
B33: W12 | C33: Review: re-read your Week 1 notes; document how your mental model changed | D33: Your own notes from Weeks 1–11 | E33: ⬜ Todo

Sheet ⚡ Inference HW
B1: ⚡ Inference Hardware Architecture — Curriculum & Progress
B2: Check off topics as you complete them. Add notes in the 'Notes' column as you go.
B4: Wk | C4: Topic / Exercise | D4: Resource | E4: Status | F4: Notes
B5: MONTH 1: JUNE — GPU Fundamentals
B6: W1 | C6: GPU architecture: SM hierarchy, CUDA cores, warp scheduling, occupancy | D6: NVIDIA CUDA Programming Guide Ch.1–4 | E6: ⬜ Todo
B7: W1 | C7: Memory hierarchy: registers → shared memory → L2 → DRAM; bandwidth vs latency | D7: Tim Dettmers 'GPU for Deep Learning' blog | E7: ⬜ Todo
B8: W2 | C8: CUDA kernel writing: thread blocks, grids, shared memory tile; profile with Nsight | D8: CUDA by Example (book); GPU Mode Lecture 1 | E8: ⬜ Todo
B9: W2 | C9: Matrix multiply: naive → tiled → cuBLAS; measure FLOP/s and bandwidth utilisation | D9: CUTLASS repo; Simon Boehm blog on GEMM | E9: ⬜ Todo
B10: W3 | C10: Inference bottlenecks: arithmetic intensity, memory-bound vs compute-bound, roofline model | D10: Roofline model paper; Dissecting the A100 (MLSys 2022) | E10: ⬜ Todo
B11: W3 | C11: KV cache: why it exists, memory footprint formula, GQA / MQA variants | D11: Efficient Transformers survey; GQA paper | E11: ⬜ Todo
B12: W4 | C12: FlashAttention: IO-aware tiling, SRAM reuse, backward pass summary | D12: FlashAttention-2 paper (Dao, 2023) | E12: ⬜ Todo
B13: W4 | C13: Paged attention: vLLM's PagedAttention — OS memory management analogy | D13: vLLM paper (Kwon et al., 2023) | E13: ⬜ Todo
B15: MONTH 2: JULY — Metal, macOS & AMD
B16: W5 | C16: Apple Silicon: Unified Memory architecture, bandwidth, Neural Engine TOPS | D16: Apple Silicon M4 whitepaper; MLX docs | E16: ⬜ Todo
B17: W5 | C17: Metal compute shaders: thread groups, threadgroup memory — conceptual vs CUDA | D17: Apple Metal Shading Language Spec | E17: ⬜ Todo
B18: W6 | C18: MLX framework: run Mistral-7B / Phi-3 on Mac; measure tokens/sec and memory use | D18: MLX GitHub repo; mlx-lm examples | E18: ⬜ Todo
B19: W6 | C19: MLX internals: lazy evaluation, unified memory ops, metal backend | D19: MLX design doc; Awni Hannun talk | E19: ⬜ Todo
B20: W7 | C20: AMD RDNA/CDNA architecture: wavefronts, LDS, MI300X for inference | D20: AMD ROCm docs; AMD MI300X whitepaper | E20: ⬜ Todo
B21: W7 | C21: HIP programming: porting a CUDA kernel to HIP; ROCm profiling tools | D21: ROCm HIP docs; Hipify tool | E21: ⬜ Todo
B22: W8 | C22: Operator fusion: fusing LayerNorm + attention; why it reduces memory traffic | D22: Triton programming guide; flash-attention Triton kernel | E22: ⬜ Todo
B23: W8 | C23: INT8 / INT4 quantised kernels: GPTQ kernel, AWQ kernel — how weights are packed | D23: GPTQ kernel repo; AWQ paper | E23: ⬜ Todo
B25: MONTH 3: AUGUST — Custom Silicon & Serving
B26: W9 | C26: Groq LPU: deterministic SRAM-only execution, streaming, compiler-driven parallelism | D26: Groq architecture whitepaper; Groq blog posts | E26: ⬜ Todo
B27: W9 | C27: Inference latency vs throughput trade-offs on Groq vs GPU | D27: Groq benchmark comparisons | E27: ⬜ Todo
B28: W10 | C28: Cerebras wafer-scale: dataflow architecture, no memory hierarchy, sparse tensor cores | D28: Cerebras CS-3 whitepaper | E28: ⬜ Todo
B29: W10 | C29: Qualcomm AI 100 Ultra: heterogeneous compute, on-device inference for edge robotics | D29: Qualcomm AI 100 whitepaper; QNN SDK docs | E29: ⬜ Todo
B30: W11 | C30: vLLM serving: continuous batching, PagedAttention, multi-GPU tensor parallelism | D30: vLLM GitHub; Anyscale serving blog | E30: ⬜ Todo
B31: W11 | C31: TensorRT-LLM: NVIDIA's high-performance inference engine, plugin system | D31: TensorRT-LLM docs; NVIDIA blog | E31: ⬜ Todo
B32: W12 | C32: Personal synthesis: hardware selection guide for an edge robotics inference workload | D32: Combine roofline, chip specs, and power budget | E32: ⬜ Todo
B33: W12 | C33: Compare: latency/power/cost table for GPU vs Apple M4 vs Groq for a given model | D33: Benchmarks you ran + published data | E33: ⬜ Todo

Sheet 🤝 Tech Sales
B1: 🤝 Technical Sales (Robotics) — Curriculum & Progress
B2: Check off topics as you complete them. Add notes in the 'Notes' column as you go.
B4: Wk | C4: Topic / Exercise | D4: Resource | E4: Status | F4: Notes
B5: MONTH 1: JUNE — Methodology Foundations
B6: W1 | C6: Read 'The Challenger Sale': core Challenger model, teaching, tailoring, taking control | D6: The Challenger Sale — Dixon & Adamson | E6: ⬜ Todo
B7: W1 | C7: MEDDIC: Metrics, Economic Buyer, Decision Criteria, Decision Process, Identify Pain, Champion | D7: MEDDIC Academy (meddic.com) | E7: ⬜ Todo
B8: W2 | C8: ICP definition: map logistics AMR / agriculture / manufacturing cobot customer profiles | D8: Augmentifai Sales GTM Skill (internal) | E8: ⬜ Todo
B9: W2 | C9: Buyer personas: Fleet Ops Manager, CTO, DevOps Lead, SRE — pain, language, objections | D9: Augmentifai Sales GTM Skill (internal) | E9: ⬜ Todo
B10: W3 | C10: Discovery call framework: 5 high-value opening questions; active listening drills | D10: SPIN Selling — Neil Rackham (Ch. 1–4) | E10: ⬜ Todo
B11: W3 | C11: Economic Buyer identification: signs you're talking to a champion vs decision-maker | D11: MEDDIC Academy | E11: ⬜ Todo
B12: W4 | C12: Value proposition: craft 30-sec / 2-min / 10-min pitch for Synapse Debugger | D12: Augmentifai concept + company skills (internal) | E12: ⬜ Todo
B13: W4 | C13: Record and review your pitch: watch for pace, filler, and clarity of the 'so what' | D13: Voice Memos / Loom | E13: ⬜ Todo
B15: MONTH 2: JULY — Robotics Domain & Demo
B16: W5 | C16: ROS2 fundamentals: nodes, topics, services, actions; common robotics failure modes | D16: ROS2 Documentation (docs.ros.org); YouTube intro | E16: ⬜ Todo
B17: W5 | C17: Fleet management systems: FMS architecture, common vendors, pain points at scale | D17: Vendor websites; Robotics Business Review | E17: ⬜ Todo
B18: W6 | C18: Competitive battle card: top 3 Augmentifai competitors — differentiators, weaknesses | D18: Augmentifai Sales GTM Skill (internal) | E18: ⬜ Todo
B19: W6 | C19: Objection handling: practise 5 common objections aloud with responses | D19: Gong Revenue Intelligence Blog | E19: ⬜ Todo
B20: W7 | C20: Demo structure: problem → demo → value — 20-minute Synapse Debugger demo outline | D20: Augmentifai Synapse Skill (internal) | E20: ⬜ Todo
B21: W7 | C21: Record and review the demo: note where energy drops and where clarity is low | D21: Loom / Voice Memos | E21: ⬜ Todo
B22: W8 | C22: Proof-of-value (POV) design: success criteria, timeline, owner, metrics, exit criteria | D22: MEDDIC POV framework | E22: ⬜ Todo
B23: W8 | C23: POV objection: 'we don't have time' — practice the response 5 times | D23: 30 Min to President's Club Podcast | E23: ⬜ Todo
B25: MONTH 3: AUGUST — Pipeline & Applied Selling
B26: W9 | C26: Write 10 personalised cold outreach emails targeting logistics AMR ICP | D26: Smart Brevity framework; Augmentifai GTM Skill | E26: ⬜ Todo
B27: W9 | C27: LinkedIn outreach: 5 targeted connection messages with a clear value hook | D27: LinkedIn Sales Navigator best practices | E27: ⬜ Todo
B28: W10 | C28: Negotiation basics: BATNA, anchoring, concession ladder, 'if you... then I...' | D28: Never Split the Difference — Chris Voss (Ch. 1–3) | E28: ⬜ Todo
B29: W10 | C29: Role-play 2 closing scenarios: budget objection and 'need to think about it' | D29: Practice partner or record solo | E29: ⬜ Todo
B30: W11 | C30: CRM pipeline discipline: build mock pipeline in Friday PM with 5 dummy deals | D30: Friday PM MCP tools (internal) | E30: ⬜ Todo
B31: W11 | C31: Weekly deal review: practise 3-min verbal update per deal — status, next step, risk | D31: Salesforce / Gong deal review methodology | E31: ⬜ Todo
B32: W12 | C32: Full mock sales cycle: discovery → demo → objection → close (full recorded session) | D32: All of the above | E32: ⬜ Todo
B33: W12 | C33: Debrief and score: use MEDDIC scorecard on the mock deal — what would you do differently? | D33: MEDDIC Academy scorecard template | E33: ⬜ Todo

Sheet 🗣️ Communication
B1: 🗣️ Communication Skills — Curriculum & Progress
B2: Check off topics as you complete them. Add notes in the 'Notes' column as you go.
B4: Wk | C4: Topic / Exercise | D4: Resource | E4: Status | F4: Notes
B5: MONTH 1: JUNE — Structure & Clarity
B6: W1 | C6: Read The Pyramid Principle: SCQA framework, inductive vs deductive ordering | D6: The Pyramid Principle — Barbara Minto (Ch. 1–3) | E6: ⬜ Todo
B7: W1 | C7: Apply SCQA: rewrite 3 real emails using the Situation-Complication-Question-Answer structure | D7: Your own inbox | E7: ⬜ Todo
B8: W2 | C8: Writing audit: pick 10 recent messages — highlight vague words, buried main points, padding | D8: Hemingway App (hemingwayapp.com) | E8: ⬜ Todo
B9: W2 | C9: Find your filler patterns: list your top 5 vague/weak words (basically, very, sort of, just) | D9: Your own emails and Slack messages | E9: ⬜ Todo
B10: W3 | C10: One-idea-per-sentence: rewrite 5 paragraphs; target max 20 words per sentence | D10: On Writing Well — Zinsser (Ch. 2–4) | E10: ⬜ Todo
B11: W3 | C11: Lead with the conclusion: practice starting every response with the answer, not the context | D11: Smart Brevity — Axios | E11: ⬜ Todo
B12: W4 | C12: 1-sentence summary discipline: after every meeting, write one sentence summarising the decision | D12: Apply in Friday PM task notes | E12: ⬜ Todo
B13: W4 | C13: Weekly writing challenge: write a 5-bullet weekly update that a C-level could read in 60 seconds | D13: BLUF format guide | E13: ⬜ Todo
B15: MONTH 2: JULY — Conciseness & Precision
B16: W5 | C16: Active voice practice: identify passive sentences in 5 docs/emails; rewrite all | D16: Elements of Style — Strunk & White (Rule 14) | E16: ⬜ Todo
B17: W5 | C17: Cut 20%: take any piece of writing and reduce it by 20% without losing meaning | D17: On Writing Well — Ch. 7 | E17: ⬜ Todo
B18: W6 | C18: Verbal 3-point answers: practice the 'position → reason → example' structure in conversations | D18: Toastmasters Table Topics format | E18: ⬜ Todo
B19: W6 | C19: Record 3 verbal responses to 'tell me about X' questions; listen for filler and rambling | D19: Voice Memos app | E19: ⬜ Todo
B20: W7 | C20: The smart brief: write a 5-line project update that replaces a 30-minute meeting | D20: Axios Smart Brevity format | E20: ⬜ Todo
B21: W7 | C21: Async-first writing: practice the principle of 'no meeting if a message would do' | D21: Doist's Guide to Async Communication | E21: ⬜ Todo
B22: W8 | C22: Presentation clarity: for any 10-min topic, write an opening hook (1 sentence), 3 points, close | D22: TED Talk structure analysis | E22: ⬜ Todo
B23: W8 | C23: Peer feedback: send 3 emails to a trusted colleague and ask for honest clarity feedback | D23: Use a simple scorecard: clear? concise? actionable? | E23: ⬜ Todo
B25: MONTH 3: AUGUST — Executive Communication
B26: W9 | C26: BLUF for leadership: practice 'Bottom Line Up Front' format for any upward communication | D26: US Army BLUF doctrine; exec writing guides | E26: ⬜ Todo
B27: W9 | C27: Executive email template: subject (outcome), 2-line summary, 3 bullets, clear ask | D27: Your own templates | E27: ⬜ Todo
B28: W10 | C28: Presentation structure: opening hook → insight 1 → 2 → 3 → call to action. 10-min practice talk | D28: Garr Reynolds 'Presentation Zen' (book/blog) | E28: ⬜ Todo
B29: W10 | C29: Speaking clarity drill: record yourself explaining a complex topic to a 12-year-old | D29: Voice Memos; share with a non-technical friend | E29: ⬜ Todo
B30: W11 | C30: Feedback loop: ask a colleague weekly for one thing to improve in your communication | D30: Use a specific question: 'Was my last update clear and direct?' | E30: ⬜ Todo
B31: W11 | C31: Conflict communication: practice delivering difficult news clearly and kindly (role-play) | D31: Crucial Conversations — Patterson et al. (Ch. 1–3) | E31: ⬜ Todo
B32: W12 | C32: Personal style guide: document your 10 communication rules — your own cheat sheet | D32: Print and keep visible at desk | E32: ⬜ Todo
B33: W12 | C33: Before/after portfolio: collect 5 examples of improved writing from Week 1 to Week 12 | D33: Side-by-side comparison document | E33: ⬜ Todo

Sheet 🎙️ Voice
B1: 🎙️ Voice & Command — Curriculum & Progress
B2: Check off topics as you complete them. Add notes in the 'Notes' column as you go.
B4: Wk | C4: Topic / Exercise | D4: Resource | E4: Status | F4: Notes
B5: MONTH 1: JUNE — Breath & Resonance (15–20 min/day)
B6: Daily | C6: Diaphragmatic breathing: 4-2-6 count, belly-first, 3 minutes | D6: Roger Love 'Set Your Voice Free' (Ch. 1–2) | E6: ⬜ Todo
B7: Daily | C7: Humming + lip trills: start at comfortable pitch, slide up and down, 3 minutes | D7: Roger Love vocal warmup exercises | E7: ⬜ Todo
B8: Daily | C8: Articulation drills: 'Red leather yellow leather' / 'Unique New York' at slow then fast pace | D8: Toastmasters tongue twister sets | E8: ⬜ Todo
B9: Daily | C9: Paced reading aloud: any text, 80% of natural speed, 4 minutes; record on phone | D9: Your own voice memos | E9: ⬜ Todo
B10: Weekly | C10: Listen back to Monday's recording; note one thing to improve | D10: Voice Memos app | E10: ⬜ Todo
B11: W1–2 | C11: Posture awareness: stand or sit tall when speaking; check shoulder and jaw tension | D11: Julian Treasure TED talk on speaking | E11: ⬜ Todo
B12: W3–4 | C12: Resonance placement: feel the vibration in chest vs head voice; practise both registers | D12: Roger Love 'Set Your Voice Free' (Ch. 3) | E12: ⬜ Todo
B13: W4 | C13: Baseline recording: record a 2-minute pitch. This is your Month 1 reference. | D13: Loom or Voice Memos — label clearly | E13: ⬜ Todo
B15: MONTH 2: JULY — Pace, Articulation & Pause
B16: Daily | C16: Continue daily 16-min routine from Month 1 | D16: Habit maintained from June | E16: ⬜ Todo
B17: Daily | C17: Deliberate pause practice: read a paragraph aloud and insert a 1-second pause after each sentence | D17: Any text; focus on resisting the urge to rush | E17: ⬜ Todo
B18: Daily | C18: Transcribe 1 minute of your own recording using Otter.ai; count filler words | D18: Otter.ai (free tier) | E18: ⬜ Todo
B19: W5 | C19: Consonant crispness: over-articulate 't', 'd', 'p', 'b' at the end of words — then normalise | D19: Classic actor vocal training exercises | E19: ⬜ Todo
B20: W6 | C20: Pace variation: read the same paragraph at 3 speeds (slow, normal, fast) — feel the difference | D20: Your own recordings; compare the effect | E20: ⬜ Todo
B21: W7 | C21: Record a 3-min monologue on any technical topic; count: umms, likes, you-knows | D21: Voice Memos; review with transcript | E21: ⬜ Todo
B22: W7 | C22: Eliminate top filler word for 1 week: replace 'um' with a pause — measure the change | D22: Transcript comparison | E22: ⬜ Todo
B23: W8 | C23: Present a 5-min topic to a friend or colleague; ask for pace and clarity feedback | D23: Real conversation practice | E23: ⬜ Todo
B25: MONTH 3: AUGUST — Projection, Tonality & Command
B26: Daily | C26: Continue full daily routine; add 2 min of projection practice (speak to back of room) | D26: Project from diaphragm, not throat | E26: ⬜ Todo
B27: Daily | C27: Vocal variety drill: read the same sentence with 3 different emotions — engage your tonal range | D27: Any paragraph; experiment freely | E27: ⬜ Todo
B28: W9 | C28: Confident word endings: do NOT drop your voice at the end of statements (downward inflection) | D28: Record and check: does your energy stay up to the last word? | E28: ⬜ Todo
B29: W10 | C29: Tonality map: identify your 3 go-to tones (explaining, persuading, questioning) — practise each | D29: Roger Love on tonal variety | E29: ⬜ Todo
B30: W11 | C30: Live presentation: deliver a 5-min talk in a real meeting, webinar, or event | D30: Request 2 pieces of specific voice feedback afterwards | E30: ⬜ Todo
B31: W11 | C31: Synapse Debugger pitch: record the full 2-min pitch — your Month 3 reference recording | D31: Compare to your Month 1 baseline from Week 4 | E31: ⬜ Todo
B32: W12 | C32: Side-by-side comparison: listen to Month 1 vs Month 3 recordings; write what changed | D32: Note: pace, resonance, filler frequency, confidence | E32: ⬜ Todo
B33: W12 | C33: Voice maintenance plan: write a 10-min weekly routine you will continue after August | D33: Your own reference document | E33: ⬜ Todo

Sheet 📚 Resources
B1: 📚 Master Resource Library
B2: All resources for the 3-month plan. Use the 'Status' column to track: Not Started / Reading / Done.
B4: Title / Resource | C4: Type | D4: Pillar | E4: Status
B5: Andrej Karpathy — 'Neural Networks: Zero to Hero' | C5: YouTube | D5: 🧠 LLM | E5: ⬜ Not Started
B6: Attention Is All You Need (Vaswani et al., 2017) | C6: Paper | D6: 🧠 LLM | E6: ⬜ Not Started
B7: InstructGPT Paper (Ouyang et al., 2022) | C7: Paper | D7: 🧠 LLM | E7: ⬜ Not Started
B8: DPO Paper (Rafailov et al., 2023) | C8: Paper | D8: 🧠 LLM | E8: ⬜ Not Started
B9: Constitutional AI Paper (Bai et al., 2022) | C9: Paper | D9: 🧠 LLM | E9: ⬜ Not Started
B10: Lilian Weng's Blog (lilianweng.github.io) | C10: Blog | D10: 🧠 LLM | E10: ⬜ Not Started
B11: Sebastian Raschka — 'Build an LLM from Scratch' | C11: Book/Code | D11: 🧠 LLM | E11: ⬜ Not Started
B12: Hugging Face Course | C12: Course | D12: 🧠 LLM | E12: ⬜ Not Started
B13: Mamba Paper (Gu & Dao, 2023) | C13: Paper | D13: 🧠 LLM | E13: ⬜ Not Started
B14: NVIDIA CUDA Programming Guide | C14: Docs | D14: ⚡ HW | E14: ⬜ Not Started
B15: Tim Dettmers — 'GPU for Deep Learning' blog | C15: Blog | D15: ⚡ HW | E15: ⬜ Not Started
... B39: Voice Memos (daily recordings) | C39: Tool | D39: 🎙️ Voice | E39: ⬜ Not Started
